Workbook

Sheet Monthly_Data
A1: MONTHLY BASE DATA SHEET – SOURCE FOR ALL KRI CALCULATIONS
A2: Metric | B2: Unit | C2: May-25 | D2: Jun-25 | E2: Jul-25 | F2: Aug-25 | G2: Sep-25 | H2: Oct-25 | I2: Nov-25 | J2: Dec-25 | K2: Jan-26 | L2: Feb-26 | M2: Mar-26 | N2: Apr-26 | O2: Source | P2: Formula / Note
A3: --- CREDIT RISK --- | O3: P1_Credit_Risk
A4: Gross NPA Amount (₹ Cr) | B4: ₹ Cr | C4: 16640 | D4: 16290 | E4: 15750 | F4: 15390 | G4: 15120 | H4: 14820 | I4: 14550 | J4: 14250 | K4: 13940 | L4: 13940 | M4: 14250 | N4: 14250 | O4: P1_Credit_Risk | P4: SUMIF(NPA_Category<>Standard, Outstanding)
A5: Gross Advances (₹ Cr) | B5: ₹ Cr | C5: 286900 | D5: 285900 | E5: 286200 | F5: 285100 | G5: 285400 | H5: 284800 | I5: 285200 | J5: 285000 | K5: 284700 | L5: 284600 | M5: 285000 | N5: 285000 | O5: P1_Credit_Risk | P5: SUM(Outstanding_Cr)
A6: Net NPA Amount (₹ Cr) | B6: ₹ Cr | C6: 8035 | D6: 7727 | E6: 7446 | F6: 7128 | G6: 6840 | H6: 6552 | I6: 6270 | J6: 5985 | K6: 5985 | L6: 5700 | M6: 5985 | N6: 5985 | O6: P1_Credit_Risk | P6: Gross NPA – Provisions held
A7: Net Advances (₹ Cr) | B7: ₹ Cr | C7: 286900 | D7: 285900 | E7: 286200 | F7: 285100 | G7: 285400 | H7: 284800 | I7: 285200 | J7: 285000 | K7: 284700 | L7: 284600 | M7: 285000 | N7: 285000 | O7: P1_Credit_Risk | P7: Gross Adv – Total Provisions
A8: SMA-0 Balance (₹ Cr) | B8: ₹ Cr | C8: 9726 | D8: 9440 | E8: 9589 | F8: 9609 | G8: 9572 | H8: 9377 | I8: 9177 | J8: 9120 | K8: 9120 | L8: 9120 | M8: 9120 | N8: 9120 | O8: P1_Credit_Risk | P8: SUMIF(SMA_Flag=SMA-0, Outstanding)
A9: SMA-1 Balance (₹ Cr) | B9: ₹ Cr | C9: 3446 | D9: 3202 | E9: 3161 | F9: 3159 | G9: 3151 | H9: 3302 | I9: 3304 | J9: 3420 | K9: 3420 | L9: 3420 | M9: 3420 | N9: 3420 | O9: P1_Credit_Risk | P9: SUMIF(SMA_Flag=SMA-1, Outstanding)
A10: SMA-2 Balance (₹ Cr) | B10: ₹ Cr | C10: 1721 | D10: 1751 | E10: 1723 | F10: 1720 | G10: 1714 | H10: 1709 | I10: 1705 | J10: 1995 | K10: 1995 | L10: 1995 | M10: 1995 | N10: 1995 | O10: P1_Credit_Risk | P10: SUMIF(SMA_Flag=SMA-2, Outstanding)
A11: Total Provisions (₹ Cr) | B11: ₹ Cr | C11: 12652 | D11: 12600 | E11: 12350 | F11: 12300 | G11: 12318 | H11: 12319 | I11: 12320 | J11: 12330 | K11: 12000 | L11: 12260 | M11: 12330 | N11: 12330 | O11: P1_Credit_Risk | P11: SUM(ECL_Cr)
A12: PCR Provisions (₹ Cr) | B12: ₹ Cr | C12: 12652 | D12: 11681 | E12: 11692 | F12: 10851 | G12: 10911 | H12: 10817 | I12: 11058 | J12: 10830 | K12: 10829 | L12: 10829 | M12: 10830 | N12: 10830 | O12: P1_Credit_Risk | P12: Provisions / Gross NPA * 100
A13: ECL Stage 3 EAD (₹ Cr) | B13: ₹ Cr | C13: 16640 | D13: 16290 | E13: 15750 | F13: 15390 | G13: 15120 | H13: 14820 | I13: 14550 | J13: 14250 | K13: 13940 | L13: 13940 | M13: 14250 | N13: 14250 | O13: ECL Engine | P13: Stage 3 Exposure at Default
A14: ECL Stage 3 Provisions (₹Cr) | B14: ₹ Cr | C14: 10234 | D14: 10027 | E14: 9945 | F14: 9752 | G14: 9645 | H14: 9408 | I14: 9249 | J14: 8992 | K14: 8808 | L14: 8808 | M14: 8992 | N14: 8992 | O14: ECL Engine | P14: Provisions held against Stage 3
A15: --- MARKET RISK --- | O15: P1_Market_Risk
A16: Trading Book VaR 1D (₹ Cr) | B16: ₹ Cr | C16: 720 | D16: 680 | E16: 660 | F16: 665 | G16: 630 | H16: 640 | I16: 640 | J16: 650 | K16: 650 | L16: 640 | M16: 640 | N16: 640 | O16: Treasury/Murex | P16: PERCENTILE(VaR_1D_Cr, 99%)
A17: VaR Limit (₹ Cr) | B17: ₹ Cr | C17: 1000 | D17: 1000 | E17: 1000 | F17: 1000 | G17: 1000 | H17: 1000 | I17: 1000 | J17: 1000 | K17: 1000 | L17: 1000 | M17: 1000 | N17: 1000 | O17: Treasury/Murex | P17: Board approved limit
A18: SVaR Total (₹ Cr) | B18: ₹ Cr | C18: 4250 | D18: 4300 | E18: 4280 | F18: 4210 | G18: 4150 | H18: 4100 | I18: 4080 | J18: 4060 | K18: 4050 | L18: 4050 | M18: 4050 | N18: 4050 | O18: Treasury/Murex | P18: SUM(SVaR_Cr)
A19: IRC Total (₹ Cr) | B19: ₹ Cr | C19: 1820 | D19: 1800 | E19: 1780 | F19: 1760 | G19: 1750 | H19: 1740 | I19: 1730 | J19: 1720 | K19: 1720 | L19: 1720 | M19: 1720 | N19: 1720 | O19: Treasury/Murex | P19: SUM(IRC_Cr)
A20: FX Open Position (₹ Cr) | B20: ₹ Cr | C20: 92 | D20: 94 | E20: 91 | F20: 88 | G20: 85 | H20: 87 | I20: 88 | J20: 89 | K20: 90 | L20: 88 | M20: 88 | N20: 88 | O20: SWIFT/Murex | P20: Net open FX position
A21: DV01 Total (₹ Lakhs) | B21: ₹ Lk | C21: 5420 | D21: 5380 | E21: 5350 | F21: 5320 | G21: 5290 | H21: 5260 | I21: 5240 | J21: 5220 | K21: 5200 | L21: 5200 | M21: 5200 | N21: 5200 | O21: Murex | P21: SUM(DV01_Lakhs)
A22: DV01 Limit (₹ Lakhs) | B22: ₹ Lk | C22: 9000 | D22: 9000 | E22: 9000 | F22: 9000 | G22: 9000 | H22: 9000 | I22: 9000 | J22: 9000 | K22: 9000 | L22: 9000 | M22: 9000 | N22: 9000 | O22: Murex | P22: Board approved limit
A23: --- OPERATIONAL RISK --- | O23: P1_Operational_Risk
A24: Op Loss Net (₹ Cr) | B24: ₹ Cr | C24: 0.14 | D24: 0.13 | E24: 0.13 | F24: 0.12 | G24: 0.13 | H24: 0.12 | I24: 0.12 | J24: 0.12 | K24: 0.12 | L24: 0.11 | M24: 0.12 | N24: 0.12 | O24: ORMS | P24: SUM Net_Loss_Lakhs per month
A25: NII (Net Interest Income ₹Cr) | B25: ₹ Cr | C25: 11667 | D25: 11667 | E25: 11667 | F25: 11667 | G25: 11667 | H25: 11667 | I25: 11667 | J25: 11667 | K25: 11667 | L25: 11667 | M25: 11667 | N25: 11667 | O25: P&L | P25: Monthly NII figure
A26: KCI Breach Count | B26: Count | C26: 3 | D26: 3 | E26: 3 | F26: 3 | G26: 3 | H26: 3 | I26: 3 | J26: 3 | K26: 3 | L26: 3 | M26: 3 | N26: 3 | O26: ORMS | P26: COUNTIF(KRI_Breach=Yes)
A27: Overdue Actions | B27: Count | C27: 20 | D27: 20 | E27: 19 | F27: 18 | G27: 18 | H27: 18 | I27: 18 | J27: 18 | K27: 18 | L27: 18 | M27: 18 | N27: 18 | O27: GRC Tool | P27: COUNTIF(Status=Overdue)
A28: --- CAPITAL ADEQUACY --- | O28: P1_Capital_Adequacy
A29: CET1 Capital (₹ Cr) | B29: ₹ Cr | C29: 356000 | D29: 358000 | E29: 360000 | F29: 362000 | G29: 364000 | H29: 366000 | I29: 366000 | J29: 366000 | K29: 359199 | L29: 362448 | M29: 366393 | N29: 372064 | O29: CAR Return | P29: From quarterly CAR return (interpolated monthly)
A30: Tier1 Capital (₹ Cr) | B30: ₹ Cr | C30: 374000 | D30: 376000 | E30: 378000 | F30: 380000 | G30: 382000 | H30: 384000 | I30: 384000 | J30: 384000 | K30: 379036 | L30: 382633 | M30: 386361 | N30: 392022 | O30: CAR Return
A31: Total Capital (₹ Cr) | B31: ₹ Cr | C31: 436000 | D31: 438000 | E31: 440000 | F31: 442000 | G31: 444000 | H31: 446000 | I31: 446000 | J31: 446000 | K31: 444897 | L31: 448727 | M31: 454008 | N31: 460108 | O31: CAR Return
A32: Total RWA (₹ Cr) | B32: ₹ Cr | C32: 2280000 | D32: 2285000 | E32: 2290000 | F32: 2295000 | G32: 2300000 | H32: 2305000 | I32: 2310000 | J32: 2315000 | K32: 2300775 | L32: 2323874 | M32: 2363920 | N32: 2381080 | O32: CAR Return
A33: Tier1 (Leverage Exposure₹Cr) | B33: ₹ Cr | C33: 24800000 | D33: 24900000 | E33: 25000000 | F33: 25100000 | G33: 25200000 | H33: 25300000 | I33: 25400000 | J33: 25500000 | K33: 25357612 | L33: 24654381 | M33: 26351120 | N33: 25265818 | O33: CAR Return | P33: Exposure measure for leverage ratio
A34: --- LIQUIDITY --- | O34: P2_Liquidity_Risk
A35: HQLA Total (₹ Cr) | B35: ₹ Cr | C35: 6800 | D35: 7100 | E35: 7200 | F35: 7500 | G35: 7600 | H35: 7800 | I35: 8000 | J35: 8200 | K35: 8400 | L35: 8500 | M35: 8200 | N35: 8200 | O35: ALM System | P35: AVERAGE(HQLA_Cr) for month
A36: Net Cash Outflow 30D (₹ Cr) | B36: ₹ Cr | C36: 5763 | D36: 5917 | E36: 5902 | F36: 6048 | G36: 6080 | H36: 6191 | I36: 6299 | J36: 6406 | K36: 6512 | L36: 6538 | M36: 6406 | N36: 6406 | O36: ALM System | P36: AVERAGE(Net_Cash_Outflow_30D_Cr)
A37: NSFR ASF (₹ Cr) | B37: ₹ Cr | C37: 130000 | D37: 131000 | E37: 132000 | F37: 133000 | G37: 134000 | H37: 135000 | I37: 136000 | J37: 137000 | K37: 138000 | L37: 139000 | M37: 137000 | N37: 137000 | O37: ALM System | P37: AVERAGE(NSFR_ASF_Cr)
A38: NSFR RSF (₹ Cr) | B38: ₹ Cr | C38: 120000 | D38: 120183 | E38: 120000 | F38: 119800 | G38: 120721 | H38: 120536 | I38: 121429 | J38: 121239 | K38: 123214 | L38: 123009 | M38: 121239 | N38: 121239 | O38: ALM System | P38: AVERAGE(NSFR_RSF_Cr)
A39: SLR (% NDTL) | B39: % | C39: 23.06 | D39: 21.85 | E39: 22.06 | F39: 22.82 | G39: 23.25 | H39: 22.62 | I39: 22.71 | J39: 22.6 | K39: 23.06 | L39: 22.6 | M39: 22.6 | N39: 22.6 | O39: CBS | P39: Fortnightly SLR filing
A40: CRR (% NDTL) | B40: % | C40: 4 | D40: 4.5 | E40: 4.5 | F40: 4.5 | G40: 4 | H40: 4.5 | I40: 4.5 | J40: 4.5 | K40: 4 | L40: 4.5 | M40: 4.5 | N40: 4.5 | O40: CBS | P40: Fortnightly CRR filing
...

Sheet Table_of_Contents
A1: BANK – ENTERPRISE RISK MANAGEMENT DASHBOARD Table of Contents
A2: # | B2: Sheet Name | C2: Description | D2: Pillar | E2: Last Updated
A3: 1 | B3: KRI_Master_Summary | C3: Master KRI tracker – all risk types with RAG status | D3: All Pillars | E3: Apr-2026
A4: 2 | B4: KRI_Thresholds | C4: Threshold definitions & breach logic for every KRI | D4: All Pillars | E4: Apr-2026
A5: 3 | B5: P1_Credit_Risk | C5: Pillar 1 – Credit risk: NPA, ECL, PD, LGD, CRAR by segment | D5: Pillar 1 | E5: Apr-2026
A6: 4 | B6: P1_Market_Risk | C6: Pillar 1 – Market risk: VaR, SVaR, IRC, DV01, limits | D6: Pillar 1 | E6: Apr-2026
A7: 5 | B7: P1_Operational_Risk | C7: Pillar 1 – Op risk: loss events, RCSA, BIA capital | D7: Pillar 1 | E7: Apr-2026
A8: 6 | B8: P1_Capital_Adequacy | C8: Pillar 1 – CRAR, Tier-1, CET-1, RWA by risk type | D8: Pillar 1 | E8: Apr-2026
A9: 7 | B9: P2_Liquidity_Risk | C9: Pillar 2 – LCR, NSFR, SLR, CRR, gap analysis | D9: Pillar 2 | E9: Apr-2026
A10: 8 | B10: P2_IRRBB | C10: Pillar 2 – IRRBB: NII sensitivity, EVE shock, duration gap | D10: Pillar 2 | E10: Apr-2026
A11: 9 | B11: P2_Concentration_Risk | C11: Pillar 2 – Single-borrower, sector & geography concentration | D11: Pillar 2 | E11: Apr-2026
A12: 10 | B12: P2_Climate_Risk | C12: Pillar 2 – Physical & transition risk, TCFD, GHG, ESG | D12: Pillar 2 | E12: Apr-2026
A13: 11 | B13: P2_Cyber_Risk | C13: Pillar 2 – Cyber incidents, CVSS, MTTD, MTTR | D13: Pillar 2 | E13: Apr-2026
A14: 12 | B14: P2_Fraud_Risk | C14: Pillar 2 – Fraud detection, channel, recovery rate | D14: Pillar 2 | E14: Apr-2026
... A20: 18 | B20: Monthly_KRI_Trend | C20: 12-month KRI trend for executive dashboard | D20: All Pillars | E20: Apr-2026

Sheet KRI_Master_Summary
A1: KRI MASTER SUMMARY – ENTERPRISE RISK DASHBOARD | Reference: /RMD/CCRMD/2025-26/01 | Current Values & MoM: FORMULA-DRIVEN from Monthly_KRI_Trend → Monthly_Data
A2: # | B2: Risk Category | C2: KRI Name | D2: Current Value | E2: Threshold (Green) | F2: Threshold (Amber) | G2: Threshold (Red) | H2: Unit | I2: Frequency | J2: RAG Status | K2: MoM Change | L2: Data Source | M2: Regulatory Ref | N2: KRI_Score | O2: Breach_Flag
A3: 1 | B3: Pillar 1 – Credit Risk | C3: Gross NPA Ratio | D3: =IFERROR(Monthly_KRI_Trend!T4,"") -> 5 | E3: <5% | F3: 5-6% | G3: >6% | H3: Percent | I3: Monthly | J3: =IFERROR(IF(Monthly_KRI_Trend!D4="Lower Better",IF(Monthly_KRI_Trend!T4<Monthly_KRI_Trend!F4,"Green",IF(Monthly_KRI_Trend!T4<Monthly_KRI_Trend!E4,"Amber","Red")),IF(Monthly_KRI_Trend!T4>Monthly_KRI_Trend!F4,"Green",IF(Monthly_KRI_Trend!T4>Monthly_KRI_Trend!E4,"Amber","Red"))),"") -> Amber | K3: +1.02% | L3: =IFERROR(Monthly_KRI_Trend!V4,"") -> 0 | M3: IRAC Norms | N3: =IF(J3="Green",1,IF(J3="Amber",2,IF(J3="Red",3,""))) -> 2 | O3: =IF(J3="Red","YES",IF(J3="Amber","WATCH","OK")) -> WATCH
A4: 2 | B4: Pillar 1 – Credit Risk | C4: Net NPA Ratio | D4: =IFERROR(Monthly_KRI_Trend!T5,"") -> 2.1 | E4: <2% | F4: 2-3% | G4: >3% | H4: Percent | I4: Monthly | J4: =IFERROR(IF(Monthly_KRI_Trend!D5="Lower Better",IF(Monthly_KRI_Trend!T5<Monthly_KRI_Trend!F5,"Green",IF(Monthly_KRI_Trend!T5<Monthly_KRI_Trend!E5,"Amber","Red")),IF(Monthly_KRI_Trend!T5>Monthly_KRI_Trend!F5,"Green",IF(Monthly_KRI_Trend!T5>Monthly_KRI_Trend!E5,"Amber","Red"))),"") -> Amber | K4: -2.36% | L4: =IFERROR(Monthly_KRI_Trend!V5,"") -> 0 | M4: IRAC Norms | N4: =IF(J4="Green",1,IF(J4="Amber",2,IF(J4="Red",3,""))) -> 2 | O4: =IF(J4="Red","YES",IF(J4="Amber","WATCH","OK")) -> WATCH
A5: 3 | B5: Pillar 1 – Credit Risk | C5: Credit Cost (Provisioning Ratio) | D5: =IFERROR(IF(Monthly_Data!N5=0,"",ROUND((Monthly_Data!N11/Monthly_Data!N5)*100,2)),"") -> 4.33 | E5: <1.5% | F5: 1.5-2% | G5: >2% | H5: Percent | I5: Quarterly | J5: =IFERROR(IF(Monthly_KRI_Trend!D6="Lower Better",IF(Monthly_KRI_Trend!T6<Monthly_KRI_Trend!F6,"Green",IF(Monthly_KRI_Trend!T6<Monthly_KRI_Trend!E6,"Amber","Red")),IF(Monthly_KRI_Trend!T6>Monthly_KRI_Trend!F6,"Green",IF(Monthly_KRI_Trend!T6>Monthly_KRI_Trend!E6,"Amber","Red"))),"") -> Amber | K5: -0.99% | L5: =IFERROR(Monthly_KRI_Trend!V6,"") -> 0 | M5: RBI MAS | N5: =IF(J5="Green",1,IF(J5="Amber",2,IF(J5="Red",3,""))) -> 2 | O5: =IF(J5="Red","YES",IF(J5="Amber","WATCH","OK")) -> WATCH
A6: 4 | B6: Pillar 1 – Credit Risk | C6: SMA-0 Ratio | D6: =IFERROR(Monthly_KRI_Trend!T6,"") -> 3.2 | E6: <3% | F6: 3-5% | G6: >5% | H6: Percent | I6: Monthly | J6: =IFERROR(IF(Monthly_KRI_Trend!D7="Lower Better",IF(Monthly_KRI_Trend!T7<Monthly_KRI_Trend!F7,"Green",IF(Monthly_KRI_Trend!T7<Monthly_KRI_Trend!E7,"Amber","Red")),IF(Monthly_KRI_Trend!T7>Monthly_KRI_Trend!F7,"Green",IF(Monthly_KRI_Trend!T7>Monthly_KRI_Trend!E7,"Amber","Red"))),"") -> Amber | K6: -1.27% | L6: =IFERROR(Monthly_KRI_Trend!V7,"") -> 0 | M6: RBI Circular | N6: =IF(J6="Green",1,IF(J6="Amber",2,IF(J6="Red",3,""))) -> 2 | O6: =IF(J6="Red","YES",IF(J6="Amber","WATCH","OK")) -> WATCH
A7: 5 | B7: Pillar 1 – Credit Risk | C7: SMA-1 Ratio | D7: =IFERROR(Monthly_KRI_Trend!T7,"") -> 1.2 | E7: <1% | F7: 1-2% | G7: >2% | H7: Percent | I7: Monthly | J7: =IFERROR(IF(Monthly_KRI_Trend!D8="Lower Better",IF(Monthly_KRI_Trend!T8<Monthly_KRI_Trend!F8,"Green",IF(Monthly_KRI_Trend!T8<Monthly_KRI_Trend!E8,"Amber","Red")),IF(Monthly_KRI_Trend!T8>Monthly_KRI_Trend!F8,"Green",IF(Monthly_KRI_Trend!T8>Monthly_KRI_Trend!E8,"Amber","Red"))),"") -> Amber | K7: +1.55% | L7: =IFERROR(Monthly_KRI_Trend!V8,"") -> 0 | M7: RBI Circular | N7: =IF(J7="Green",1,IF(J7="Amber",2,IF(J7="Red",3,""))) -> 2 | O7: =IF(J7="Red","YES",IF(J7="Amber","WATCH","OK")) -> WATCH
A8: 6 | B8: Pillar 1 – Credit Risk | C8: SMA-2 Ratio | D8: =IFERROR(Monthly_KRI_Trend!T8,"") -> 0.7 | E8: <0.5% | F8: 0.5-1% | G8: >1% | H8: Percent | I8: Monthly | J8: =IFERROR(IF(Monthly_KRI_Trend!D9="Lower Better",IF(Monthly_KRI_Trend!T9<Monthly_KRI_Trend!F9,"Green",IF(Monthly_KRI_Trend!T9<Monthly_KRI_Trend!E9,"Amber","Red")),IF(Monthly_KRI_Trend!T9>Monthly_KRI_Trend!F9,"Green",IF(Monthly_KRI_Trend!T9>Monthly_KRI_Trend!E9,"Amber","Red"))),"") -> Green | K8: +1.22% | L8: =IFERROR(Monthly_KRI_Trend!V9,"") -> 0 | M8: RBI Circular | N8: =IF(J8="Green",1,IF(J8="Amber",2,IF(J8="Red",3,""))) -> 1 | O8: =IF(J8="Red","YES",IF(J8="Amber","WATCH","OK")) -> OK
A9: 8 | B9: Pillar 1 – Credit Risk | C9: PCR (Provision Coverage Ratio) | D9: =IFERROR(Monthly_KRI_Trend!T9,"") -> 76 | E9: >75% | F9: 65-75% | G9: <65% | H9: Percent | I9: Quarterly | J9: =IFERROR(IF(Monthly_KRI_Trend!D10="Lower Better",IF(Monthly_KRI_Trend!T10<Monthly_KRI_Trend!F10,"Green",IF(Monthly_KRI_Trend!T10<Monthly_KRI_Trend!E10,"Amber","Red")),IF(Monthly_KRI_Trend!T10>Monthly_KRI_Trend!F10,"Green",IF(Monthly_KRI_Trend!T10>Monthly_KRI_Trend!E10,"Amber","Red"))),"") -> Green | K9: -2.02% | L9: =IFERROR(Monthly_KRI_Trend!V10,"") -> 0 | M9: RBI | N9: =IF(J9="Green",1,IF(J9="Amber",2,IF(J9="Red",3,""))) -> 1 | O9: =IF(J9="Red","YES",IF(J9="Amber","WATCH","OK")) -> OK
A10: 9 | B10: Pillar 1 – Credit Risk | C10: ECL Stage 3 Coverage | D10: =IFERROR(Monthly_KRI_Trend!T10,"") -> 63.101754 | E10: >60% | F10: 50-60% | G10: <50% | H10: Percent | I10: Quarterly | J10: Green | K10: -0.18% | L10: =IFERROR(Monthly_KRI_Trend!#REF!,"") | M10: Ind AS 109 | N10: =IF(J10="Green",1,IF(J10="Amber",2,IF(J10="Red",3,""))) -> 1 | O10: =IF(J10="Red","YES",IF(J10="Amber","WATCH","OK")) -> OK
A11: 13 | B11: Pillar 1 – Market Risk | C11: IRC (Incremental Risk Charge) | D11: =IFERROR(Monthly_KRI_Trend!T14,"") -> 88 | E11: <1500 | F11: 1500-2000 | G11: >2000 | H11: ₹ Cr | I11: Weekly | J11: =IFERROR(IF(Monthly_KRI_Trend!D14="Lower Better",IF(Monthly_KRI_Trend!T14<Monthly_KRI_Trend!F14,"Green",IF(Monthly_KRI_Trend!T14<Monthly_KRI_Trend!E14,"Amber","Red")),IF(Monthly_KRI_Trend!T14>Monthly_KRI_Trend!F14,"Green",IF(Monthly_KRI_Trend!T14>Monthly_KRI_Trend!E14,"Amber","Red"))),"") -> Green | K11: -2.35% | L11: =IFERROR(Monthly_KRI_Trend!V14,"") -> 0 | M11: Basel III | N11: =IF(J11="Green",1,IF(J11="Amber",2,IF(J11="Red",3,""))) -> 1 | O11: =IF(J11="Red","YES",IF(J11="Amber","WATCH","OK")) -> OK
A12: 14 | B12: Pillar 1 – Market Risk | C12: Modified Duration (Investment) | D12: 3.8 | E12: <4 | F12: 4-5 | G12: >5 | H12: Years | I12: Monthly | J12: =IFERROR(IF(Monthly_KRI_Trend!D15="Lower Better",IF(Monthly_KRI_Trend!T15<Monthly_KRI_Trend!F15,"Green",IF(Monthly_KRI_Trend!T15<Monthly_KRI_Trend!E15,"Amber","Red")),IF(Monthly_KRI_Trend!T15>Monthly_KRI_Trend!F15,"Green",IF(Monthly_KRI_Trend!T15>Monthly_KRI_Trend!E15,"Amber","Red"))),"") -> Green | K12: -1.41% | L12: =IFERROR(Monthly_KRI_Trend!V15,"") -> 0 | M12: Internal | N12: =IF(J12="Green",1,IF(J12="Amber",2,IF(J12="Red",3,""))) -> 1 | O12: =IF(J12="Red","YES",IF(J12="Amber","WATCH","OK")) -> OK
A13: 15 | B13: Pillar 1 – Market Risk | C13: G-Sec Portfolio MTM Loss | D13: -45 | E13: >-500 | F13: (-500)-(-750) | G13: <-750 | H13: ₹ Cr | I13: Daily | J13: =IFERROR(IF(Monthly_KRI_Trend!D16="Lower Better",IF(Monthly_KRI_Trend!T16<Monthly_KRI_Trend!F16,"Green",IF(Monthly_KRI_Trend!T16<Monthly_KRI_Trend!E16,"Amber","Red")),IF(Monthly_KRI_Trend!T16>Monthly_KRI_Trend!F16,"Green",IF(Monthly_KRI_Trend!T16>Monthly_KRI_Trend!E16,"Amber","Red"))),"") -> Green | K13: +1.07% | L13: =IFERROR(Monthly_KRI_Trend!V16,"") -> 0 | M13: Internal | N13: =IF(J13="Green",1,IF(J13="Amber",2,IF(J13="Red",3,""))) -> 1 | O13: =IF(J13="Red","YES",IF(J13="Amber","WATCH","OK")) -> OK
A14: 16 | B14: Pillar 1 – Market Risk | C14: FX Open Position (USD equiv.) | D14: =IFERROR(Monthly_KRI_Trend!T14,"") -> 88 | E14: <100 | F14: 100-150 | G14: >150 | H14: ₹ Cr | I14: Daily | J14: Green | K14: +0.5% | L14: =IFERROR(Monthly_KRI_Trend!V17,"") -> 0 | M14: FEMA / RBI | N14: =IF(J14="Green",1,IF(J14="Amber",2,IF(J14="Red",3,""))) -> 1 | O14: =IF(J14="Red","YES",IF(J14="Amber","WATCH","OK")) -> OK
A15: 17 | B15: Pillar 1 – Market Risk | C15: DV01 Limit Utilisation | D15: =IFERROR(Monthly_KRI_Trend!T15,"") -> 57.777778 | E15: <60% | F15: 60-80% | G15: >80% | H15: Percent | I15: Daily | J15: Green | K15: -1.29% | L15: =IFERROR(Monthly_KRI_Trend!V18,"") -> 0 | M15: Internal | N15: =IF(J15="Green",1,IF(J15="Amber",2,IF(J15="Red",3,""))) -> 1 | O15: =IF(J15="Red","YES",IF(J15="Amber","WATCH","OK")) -> OK
A16: 18 | B16: Pillar 1 – Market Risk | C16: Equity VaR Limit Utilisation | D16: 19.3 | E16: <50% | F16: 50-70% | G16: >70% | H16: Percent | I16: Daily | J16: =IFERROR(IF(Monthly_KRI_Trend!D19="Lower Better",IF(Monthly_KRI_Trend!T19<Monthly_KRI_Trend!F19,"Green",IF(Monthly_KRI_Trend!T19<Monthly_KRI_Trend!E19,"Amber","Red")),IF(Monthly_KRI_Trend!T19>Monthly_KRI_Trend!F19,"Green",IF(Monthly_KRI_Trend!T19>Monthly_KRI_Trend!E19,"Amber","Red"))),"") -> Green | K16: +0.74% | L16: =IFERROR(Monthly_KRI_Trend!V19,"") -> 0.11777418 | M16: Internal | N16: =IF(J16="Green",1,IF(J16="Amber",2,IF(J16="Red",3,""))) -> 1 | O16: =IF(J16="Red","YES",IF(J16="Amber","WATCH","OK")) -> OK
A17: 20 | B17: Pillar 1 – Op Risk | C17: RCSA Average Score | D17: 2.1 | E17: <2.5 | F17: 2.5-3.5 | G17: >3.5 | H17: Score (1-5) | I17: Semi-Annual | J17: =IFERROR(IF(Monthly_KRI_Trend!D21="Lower Better",IF(Monthly_KRI_Trend!T21<Monthly_KRI_Trend!F21,"Green",IF(Monthly_KRI_Trend!T21<Monthly_KRI_Trend!E21,"Amber","Red")),IF(Monthly_KRI_Trend!T21>Monthly_KRI_Trend!F21,"Green",IF(Monthly_KRI_Trend!T21>Monthly_KRI_Trend!E21,"Amber","Red"))),"") -> Red | K17: -2.46% | L17: =IFERROR(Monthly_KRI_Trend!V21,"") -> 0.08538704 | M17: Internal | N17: =IF(J17="Green",1,IF(J17="Amber",2,IF(J17="Red",3,""))) -> 3 | O17: =IF(J17="Red","YES",IF(J17="Amber","WATCH","OK")) -> YES
A18: 21 | B18: Pillar 1 – Op Risk | C18: KCI Breach Count | D18: =IFERROR(Monthly_KRI_Trend!T17,"") -> 3 | E18: <3 | F18: 3-6 | G18: >6 | H18: Count | I18: Monthly | J18: =IFERROR(IF(Monthly_KRI_Trend!D22="Lower Better",IF(Monthly_KRI_Trend!T22<Monthly_KRI_Trend!F22,"Green",IF(Monthly_KRI_Trend!T22<Monthly_KRI_Trend!E22,"Amber","Red")),IF(Monthly_KRI_Trend!T22>Monthly_KRI_Trend!F22,"Green",IF(Monthly_KRI_Trend!T22>Monthly_KRI_Trend!E22,"Amber","Red"))),"") -> Green | K18: +1.93% | L18: =IFERROR(Monthly_KRI_Trend!V22,"") -> 0 | M18: Internal | N18: =IF(J18="Green",1,IF(J18="Amber",2,IF(J18="Red",3,""))) -> 1 | O18: =IF(J18="Red","YES",IF(J18="Amber","WATCH","OK")) -> OK
A19: 22 | B19: Pillar 1 – Op Risk | C19: Overdue Action Items | D19: =IFERROR(Monthly_KRI_Trend!T18,"") -> 18 | E19: <10 | F19: 10-20 | G19: >20 | H19: Count | I19: Monthly | J19: Amber | K19: +1.34% | L19: =IFERROR(Monthly_KRI_Trend!V23,"") -> 0 | M19: Internal | N19: =IF(J19="Green",1,IF(J19="Amber",2,IF(J19="Red",3,""))) -> 2 | O19: =IF(J19="Red","YES",IF(J19="Amber","WATCH","OK")) -> WATCH
A20: 23 | B20: Pillar 1 – Op Risk | C20: BCBS 239 Compliance Score | D20: 92 | E20: >85 | F20: 75-85 | G20: <75 | H20: Percent | I20: Quarterly | J20: =IFERROR(IF(Monthly_KRI_Trend!D24="Lower Better",IF(Monthly_KRI_Trend!T24<Monthly_KRI_Trend!F24,"Green",IF(Monthly_KRI_Trend!T24<Monthly_KRI_Trend!E24,"Amber","Red")),IF(Monthly_KRI_Trend!T24>Monthly_KRI_Trend!F24,"Green",IF(Monthly_KRI_Trend!T24>Monthly_KRI_Trend!E24,"Amber","Red"))),"") -> Green | K20: -0.63% | L20: =IFERROR(Monthly_KRI_Trend!V24,"") -> 0 | M20: BCBS 239 | N20: =IF(J20="Green",1,IF(J20="Amber",2,IF(J20="Red",3,""))) -> 1 | O20: =IF(J20="Red","YES",IF(J20="Amber","WATCH","OK")) -> OK
A21: 24 | B21: Pillar 1 – Capital | C21: CRAR (Total) | D21: =IFERROR(Monthly_KRI_Trend!T19,"") -> 19.3235 | E21: >11.5% | F21: 11.6-12% | G21: <11.5% | H21: Percent | I21: Quarterly | J21: =IFERROR(IF(Monthly_KRI_Trend!D19="Lower Better",IF(Monthly_KRI_Trend!T19<Monthly_KRI_Trend!F19,"Green",IF(Monthly_KRI_Trend!T19<Monthly_KRI_Trend!E19,"Amber","Red")),IF(Monthly_KRI_Trend!T19>Monthly_KRI_Trend!F19,"Green",IF(Monthly_KRI_Trend!T19>Monthly_KRI_Trend!E19,"Amber","Red"))),"") -> Green | K21: -1.64% | L21: =IFERROR(Monthly_KRI_Trend!V19,"") -> 0.11777418 | M21: Basel III RBI | N21: =IF(J21="Green",1,IF(J21="Amber",2,IF(J21="Red",3,""))) -> 1 | O21: =IF(J21="Red","YES",IF(J21="Amber","WATCH","OK")) -> OK
A22: 25 | B22: Pillar 1 – Capital | C22: CET-1 Ratio | D22: =IFERROR(Monthly_KRI_Trend!T20,"") -> 15.62585 | E22: >5.5% | F22: 5.6-6% | G22: <5.5% | H22: Percent | I22: Quarterly | J22: =IFERROR(IF(Monthly_KRI_Trend!D20="Lower Better",IF(Monthly_KRI_Trend!T20<Monthly_KRI_Trend!F20,"Green",IF(Monthly_KRI_Trend!T20<Monthly_KRI_Trend!E20,"Amber","Red")),IF(Monthly_KRI_Trend!T20>Monthly_KRI_Trend!F20,"Green",IF(Monthly_KRI_Trend!T20>Monthly_KRI_Trend!E20,"Amber","Red"))),"") -> Green | K22: +2.76% | L22: =IFERROR(Monthly_KRI_Trend!V20,"") -> 0.12646807 | M22: RBI | N22: =IF(J22="Green",1,IF(J22="Amber",2,IF(J22="Red",3,""))) -> 1 | O22: =IF(J22="Red","YES",IF(J22="Amber","WATCH","OK")) -> OK
A23: 26 | B23: Pillar 1 – Capital | C23: Tier-1 Capital Ratio | D23: =IFERROR(Monthly_Data!N30/Monthly_Data!N32*100,"") -> 16.464042 | E23: >12% | F23: 10-12% | G23: <10% | H23: Percent | I23: Quarterly | J23: =IFERROR(IF(D23>12,"Green",IF(D23>10,"Amber","Red")),"") -> Green | K23: -0.65% | L23: =IFERROR(D23-(Monthly_Data!M30/Monthly_Data!M32*100),"") -> 0.11996051 | M23: RBI | N23: =IF(J23="Green",1,IF(J23="Amber",2,IF(J23="Red",3,""))) -> 1 | O23: =IF(J23="Red","YES",IF(J23="Amber","WATCH","OK")) -> OK
A24: 27 | B24: Pillar 1 – Capital | C24: Capital Conservation Buffer | D24: 2.5 | E24: >2.5% | F24: 2-2.4% | G24: <2.5% | H24: Percent | I24: Quarterly | J24: =IF(D24>=2.5,"Green",IF(D24>=1.875,"Amber","Red")) -> Green | K24: -1.99% | L24: 0 | M24: Basel III | N24: =IF(J24="Green",1,IF(J24="Amber",2,IF(J24="Red",3,""))) -> 1 | O24: =IF(J24="Red","YES",IF(J24="Amber","WATCH","OK")) -> OK
A25: 29 | B25: Pillar 2 – Liquidity | C25: LCR (Liquidity Coverage Ratio) | D25: =IFERROR(Monthly_KRI_Trend!T22,"") -> 128.005 | E25: >120% | F25: 100-120% | G25: <100% | H25: Percent | I25: Daily | J25: =IFERROR(IF(Monthly_KRI_Trend!D22="Lower Better",IF(Monthly_KRI_Trend!T22<Monthly_KRI_Trend!F22,"Green",IF(Monthly_KRI_Trend!T22<Monthly_KRI_Trend!E22,"Amber","Red")),IF(Monthly_KRI_Trend!T22>Monthly_KRI_Trend!F22,"Green",IF(Monthly_KRI_Trend!T22>Monthly_KRI_Trend!E22,"Amber","Red"))),"") -> Green | K25: +2.16% | L25: =IFERROR(Monthly_KRI_Trend!V22,"") -> 0 | M25: RBI | N25: =IF(J25="Green",1,IF(J25="Amber",2,IF(J25="Red",3,""))) -> 1 | O25: =IF(J25="Red","YES",IF(J25="Amber","WATCH","OK")) -> OK
A26: 30 | B26: Pillar 2 – Liquidity | C26: NSFR (Net Stable Funding Ratio) | D26: =IFERROR(Monthly_KRI_Trend!T23,"") -> 112.99994 | E26: >100% | F26: 99-100% | G26: <100% | H26: Percent | I26: Monthly | J26: =IFERROR(IF(Monthly_KRI_Trend!D23="Lower Better",IF(Monthly_KRI_Trend!T23<Monthly_KRI_Trend!F23,"Green",IF(Monthly_KRI_Trend!T23<Monthly_KRI_Trend!E23,"Amber","Red")),IF(Monthly_KRI_Trend!T23>Monthly_KRI_Trend!F23,"Green",IF(Monthly_KRI_Trend!T23>Monthly_KRI_Trend!E23,"Amber","Red"))),"") -> Green | K26: +0.82% | L26: =IFERROR(Monthly_KRI_Trend!V23,"") -> 0 | M26: RBI | N26: =IF(J26="Green",1,IF(J26="Amber",2,IF(J26="Red",3,""))) -> 1 | O26: =IF(J26="Red","YES",IF(J26="Amber","WATCH","OK")) -> OK
A27: 31 | B27: Pillar 2 – Liquidity | C27: SLR (Statutory Liquidity Ratio) | D27: =IFERROR(Monthly_KRI_Trend!T24,"") -> 22.6 | E27: >18% | F27: 18-19% | G27: <18% | H27: Percent | I27: Fortnightly | J27: =IFERROR(IF(Monthly_KRI_Trend!D24="Lower Better",IF(Monthly_KRI_Trend!T24<Monthly_KRI_Trend!F24,"Green",IF(Monthly_KRI_Trend!T24<Monthly_KRI_Trend!E24,"Amber","Red")),IF(Monthly_KRI_Trend!T24>Monthly_KRI_Trend!F24,"Green",IF(Monthly_KRI_Trend!T24>Monthly_KRI_Trend!E24,"Amber","Red"))),"") -> Green | K27: +1.94% | L27: =IFERROR(Monthly_KRI_Trend!V24,"") -> 0 | M27: RBI | N27: =IF(J27="Green",1,IF(J27="Amber",2,IF(J27="Red",3,""))) -> 1 | O27: =IF(J27="Red","YES",IF(J27="Amber","WATCH","OK")) -> OK
A28: 32 | B28: Pillar 2 – Liquidity | C28: CRR (Cash Reserve Ratio) | D28: =IFERROR(Monthly_KRI_Trend!T33,"") -> 4 | E28: >3% | F28: 2.8-2.9% | G28: <3% | H28: Percent | I28: Fortnightly | J28: =IFERROR(IF(Monthly_KRI_Trend!D33="Lower Better",IF(Monthly_KRI_Trend!T33<Monthly_KRI_Trend!F33,"Green",IF(Monthly_KRI_Trend!T33<Monthly_KRI_Trend!E33,"Amber","Red")),IF(Monthly_KRI_Trend!T33>Monthly_KRI_Trend!F33,"Green",IF(Monthly_KRI_Trend!T33>Monthly_KRI_Trend!E33,"Amber","Red"))),"") -> Green | K28: +1.51% | L28: =IFERROR(Monthly_KRI_Trend!V33,"") -> 0 | M28: RBI | N28: =IF(J28="Green",1,IF(J28="Amber",2,IF(J28="Red",3,""))) -> 1 | O28: =IF(J28="Red","YES",IF(J28="Amber","WATCH","OK")) -> OK
A29: 40 | B29: Pillar 2 – Liquidity | C29: HQLA Buffer (₹ Cr) | D29: =IFERROR(Monthly_KRI_Trend!T35,"") -> 31.5 | E29: >60 | F29: 40-60 | G29: <40 | H29: ₹ Cr | I29: Daily | J29: =IFERROR(IF(Monthly_KRI_Trend!D35="Lower Better",IF(Monthly_KRI_Trend!T35<Monthly_KRI_Trend!F35,"Green",IF(Monthly_KRI_Trend!T35<Monthly_KRI_Trend!E35,"Amber","Red")),IF(Monthly_KRI_Trend!T35>Monthly_KRI_Trend!F35,"Green",IF(Monthly_KRI_Trend!T35>Monthly_KRI_Trend!E35,"Amber","Red"))),"") -> Red | K29: +2.85% | L29: =IFERROR(Monthly_KRI_Trend!V35,"") -> 0 | M29: RBI LCR | N29: =IF(J29="Green",1,IF(J29="Amber",2,IF(J29="Red",3,""))) -> 3 | O29: =IF(J29="Red","YES",IF(J29="Amber","WATCH","OK")) -> YES
A30: 36 | B30: Pillar 2 – IRRBB | C30: EVE Sensitivity (+200bps) | D30: =IFERROR(Monthly_KRI_Trend!T28,"") -> -6.2 | E30: >-8% | F30: -8 to -12% | G30: <-12% | H30: Percent of Tier-1 | I30: Quarterly | J30: =IFERROR(IF(Monthly_KRI_Trend!D28="Lower Better",IF(Monthly_KRI_Trend!T28<Monthly_KRI_Trend!F28,"Green",IF(Monthly_KRI_Trend!T28<Monthly_KRI_Trend!E28,"Amber","Red")),IF(Monthly_KRI_Trend!T28>Monthly_KRI_Trend!F28,"Green",IF(Monthly_KRI_Trend!T28>Monthly_KRI_Trend!E28,"Amber","Red"))),"") -> Green | K30: +0.54% | L30: =IFERROR(Monthly_KRI_Trend!V28,"") -> 0 | M30: Basel IRRBB | N30: =IF(J30="Green",1,IF(J30="Amber",2,IF(J30="Red",3,""))) -> 1 | O30: =IF(J30="Red","YES",IF(J30="Amber","WATCH","OK")) -> OK
A31: 37 | B31: Pillar 2 – IRRBB | C31: Duration Gap | D31: =IFERROR(Monthly_KRI_Trend!T38,"") -> 2 | E31: <1.5 | F31: 1.5-2 | G31: >2 | H31: Years | I31: Quarterly | J31: =IFERROR(IF(Monthly_KRI_Trend!D38="Lower Better",IF(Monthly_KRI_Trend!T38<Monthly_KRI_Trend!F38,"Green",IF(Monthly_KRI_Trend!T38<Monthly_KRI_Trend!E38,"Amber","Red")),IF(Monthly_KRI_Trend!T38>Monthly_KRI_Trend!F38,"Green",IF(Monthly_KRI_Trend!T38>Monthly_KRI_Trend!E38,"Amber","Red"))),"") -> Green | K31: +2.06% | L31: =IFERROR(Monthly_KRI_Trend!V38,"") -> 0 | M31: Internal | N31: =IF(J31="Green",1,IF(J31="Amber",2,IF(J31="Red",3,""))) -> 1 | O31: =IF(J31="Red","YES",IF(J31="Amber","WATCH","OK")) -> OK
A32: 39 | B32: Pillar 2 – IRRBB | C32: MCLR Reset Sensitivity | D32: 0.65 | E32: <1% | F32: 1-1.5% | G32: >1.5% | H32: Percent NII impact | I32: Quarterly | J32: =IF(D32<1,"Green",IF(D32<=1.5,"Amber","Red")) -> Green | K32: +2.24% | L32: 0 | M32: RBI | N32: =IF(J32="Green",1,IF(J32="Amber",2,IF(J32="Red",3,""))) -> 1 | O32: =IF(J32="Red","YES",IF(J32="Amber","WATCH","OK")) -> OK
A33: 40 | B33: Pillar 2 – Concentration | C33: Single Borrower Limit Util. | D33: =IFERROR(Monthly_KRI_Trend!T41,"") -> 94.760361 | E33: <80% | F33: 80-90% | G33: >90% | H33: Percent | I33: Monthly | J33: =IFERROR(IF(Monthly_KRI_Trend!D41="Lower Better",IF(Monthly_KRI_Trend!T41<Monthly_KRI_Trend!F41,"Green",IF(Monthly_KRI_Trend!T41<Monthly_KRI_Trend!E41,"Amber","Red")),IF(Monthly_KRI_Trend!T41>Monthly_KRI_Trend!F41,"Green",IF(Monthly_KRI_Trend!T41>Monthly_KRI_Trend!E41,"Amber","Red"))),"") -> Red | K33: +0.68% | L33: =IFERROR(Monthly_KRI_Trend!V41,"") -> -1.2731895 | M33: RBI LSBE | N33: =IF(J33="Green",1,IF(J33="Amber",2,IF(J33="Red",3,""))) -> 3 | O33: =IF(J33="Red","YES",IF(J33="Amber","WATCH","OK")) -> YES
A34: 41 | B34: Pillar 2 – Concentration | C34: Group Borrower Limit Util. | D34: 72 | E34: <70% | F34: 70-80% | G34: >80% | H34: Percent | I34: Monthly | J34: Amber | K34: +1.38% | L34: DW | M34: RBI LSBE | N34: =IF(J34="Green",1,IF(J34="Amber",2,IF(J34="Red",3,""))) -> 2 | O34: =IF(J34="Red","YES",IF(J34="Amber","WATCH","OK")) -> WATCH
A35: 42 | B35: Pillar 2 – Concentration | C35: Top-10 Sector Conc. | D35: 42 | E35: <40% | F35: 40-50% | G35: >50% | H35: Percent of Advances | I35: Quarterly | J35: Amber | K35: -2.25% | L35: DW | M35: Internal | N35: =IF(J35="Green",1,IF(J35="Amber",2,IF(J35="Red",3,""))) -> 2 | O35: =IF(J35="Red","YES",IF(J35="Amber","WATCH","OK")) -> WATCH
A36: 43 | B36: Pillar 2 – Concentration | C36: Geographic HHI Score | D36: 0.18 | E36: <0.20 | F36: 0.20-0.25 | G36: >0.25 | H36: HHI Index | I36: Quarterly | J36: Green | K36: -1.25% | L36: DW | M36: Internal | N36: =IF(J36="Green",1,IF(J36="Amber",2,IF(J36="Red",3,""))) -> 1 | O36: =IF(J36="Red","YES",IF(J36="Amber","WATCH","OK")) -> OK
A37: 44 | B37: Pillar 2 – Concentration | C37: Unsecured Loan Ratio | D37: 22 | E37: <20% | F37: 20-25% | G37: >25% | H37: Percent | I37: Monthly | J37: Amber | K37: -0.91% | L37: Finacle | M37: Internal | N37: =IF(J37="Green",1,IF(J37="Amber",2,IF(J37="Red",3,""))) -> 2 | O37: =IF(J37="Red","YES",IF(J37="Amber","WATCH","OK")) -> WATCH
A38: 45 | B38: Pillar 2 – Climate | C38: Physical Risk Exposure (High) ₹Cr | D38: 4200 | E38: <4000 | F38: 4000-6000 | G38: >6000 | H38: ₹ Cr | I38: Quarterly | J38: Amber | K38: -2.06% | L38: Climate Tool | M38: NGFS/RBI | N38: =IF(J38="Green",1,IF(J38="Amber",2,IF(J38="Red",3,""))) -> 2 | O38: =IF(J38="Red","YES",IF(J38="Amber","WATCH","OK")) -> WATCH
A39: 46 | B39: Pillar 2 – Climate | C39: Transition Risk Score (Portfolio) | D39: 6.2 | E39: <5 | F39: 5-7 | G39: >7 | H39: Score (1-10) | I39: Semi-Annual | J39: Amber | K39: -1.22% | L39: Internal | M39: TCFD | N39: =IF(J39="Green",1,IF(J39="Amber",2,IF(J39="Red",3,""))) -> 2 | O39: =IF(J39="Red","YES",IF(J39="Amber","WATCH","OK")) -> WATCH
A40: 47 | B40: Pillar 2 – Climate | C40: Green Finance Ratio | D40: 9.4 | E40: >10% | F40: 7-10% | G40: <7% | H40: Percent | I40: Quarterly | J40: Amber | K40: -1.94% | L40: DW | M40: RBI | N40: =IF(J40="Green",1,IF(J40="Amber",2,IF(J40="Red",3,""))) -> 2 | O40: =IF(J40="Red","YES",IF(J40="Amber","WATCH","OK")) -> WATCH
...

Sheet P1_Credit_Risk
A1: PILLAR 1 | Credit Risk – Loan Book Details | Bank Risk Management Dashboard
A2: Loan_ID | B2: Borrower | C2: Segment | D2: Loan_Type | E2: Sanction_Amt_Cr | F2: Outstanding_Cr | G2: DPD_Days | H2: NPA_Category | I2: PD_% | J2: LGD_% | K2: EAD_Cr | L2: ECL_Cr | M2: CRAR_% | N2: Collateral | O2: Risk_Rating | P2: SMA_Flag | Q2: PCR_% | R2: Review_Date | S2: Sector | T2: Geography | U2: Status | V2: RAG
A3: LN20000 | B3: Borrower_001 | C3: Retail | D3: Home Loan | E3: 1796.72 | F3: 1026.49 | G3: 72 | H3: SMA-2 | I3: 19.38 | J3: 47.94 | K3: 1006.87 | L3: =ROUND(K3*(I3/100)*(J3/100),4) -> 93.546 | M3: 13.52 | N3: Stocks | O3: A- | P3: Yes | Q3: 76.2 | R3: 22-Oct-2024 | S3: Retail | T3: Gujarat | U3: Watch | V3: Amber
A4: LN20001 | B4: Borrower_002 | C4: Corporate | D4: Working Capital | E4: 1784.21 | F4: 606.69 | G4: 0 | H4: Standard | I4: 2.61 | J4: 21.77 | K4: 601.48 | L4: =ROUND(K4*(I4/100)*(J4/100),4) -> 3.4176 | M4: 17.52 | N4: Plant & Machinery | O4: A | P4: No | Q4: 52 | R4: 06-Oct-2025 | S4: Retail | T4: Andhra Pradesh | U4: Normal | V4: Green
A5: LN20002 | B5: Borrower_003 | C5: Retail | D5: MSME Loan | E5: 2028.37 | F5: 871.14 | G5: 0 | H5: Standard | I5: 1.22 | J5: 30.28 | K5: 912.73 | L5: =ROUND(K5*(I5/100)*(J5/100),4) -> 3.3718 | M5: 11.99 | N5: Guarantee | O5: A- | P5: No | Q5: 50.2 | R5: 17-Apr-2025 | S5: Shipping | T5: Rajasthan | U5: Normal | V5: Green
A6: LN20003 | B6: Borrower_004 | C6: SME | D6: Home Loan | E6: 519.4 | F6: 345.23 | G6: 0 | H6: Standard | I6: 1.02 | J6: 26.25 | K6: 363.56 | L6: =ROUND(K6*(I6/100)*(J6/100),4) -> 0.9734 | M6: 15.49 | N6: Clean | O6: BBB | P6: No | Q6: 74.2 | R6: 21-Apr-2024 | S6: Real Estate | T6: Telangana | U6: Normal | V6: Green
A7: LN20004 | B7: Borrower_005 | C7: Corporate | D7: Working Capital | E7: 2319.6 | F7: 2034.55 | G7: 0 | H7: Standard | I7: 1.57 | J7: 41.62 | K7: 2138.76 | L7: =ROUND(K7*(I7/100)*(J7/100),4) -> 13.9754 | M7: 12.98 | N7: Immovable Property | O7: A+ | P7: No | Q7: 59.1 | R7: 12-May-2026 | S7: Cement | T7: Andhra Pradesh | U7: Normal | V7: Green
A8: LN20005 | B8: Borrower_006 | C8: Agri | D8: Project Finance | E8: 1756.65 | F8: 1399.6 | G8: 175 | H8: Sub-Standard | I8: 42.96 | J8: 43.87 | K8: 1394.99 | L8: =ROUND(K8*(I8/100)*(J8/100),4) -> 262.9075 | M8: 20.22 | N8: FD | O8: BB | P8: Yes | Q8: 84.6 | R8: 28-Apr-2024 | S8: Infra | T8: Punjab | U8: High | V8: Red
A9: LN20006 | B9: Borrower_007 | C9: Government | D9: CC/OD | E9: 189.35 | F9: 122.19 | G9: 198 | H9: Doubtful-1 | I9: 57.85 | J9: 61.88 | K9: 121.11 | L9: =ROUND(K9*(I9/100)*(J9/100),4) -> 43.3544 | M9: 12.58 | N9: FD | O9: B | P9: Yes | Q9: 75.7 | R9: 10-Apr-2024 | S9: Retail | T9: UP | U9: High | V9: Red
A10: LN20007 | B10: Borrower_008 | C10: Personal | D10: Personal Loan | E10: 2340.03 | F10: 1027.03 | G10: 121 | H10: Sub-Standard | I10: 31.64 | J10: 43.27 | K10: 1055.88 | L10: =ROUND(K10*(I10/100)*(J10/100),4) -> 144.5566 | M10: 15.62 | N10: Clean | O10: BB | P10: Yes | Q10: 45.5 | R10: 27-Nov-2025 | S10: Retail | T10: UP | U10: High | V10: Red
A11: LN20008 | B11: Borrower_009 | C11: SME | D11: Home Loan | E11: 1289.42 | F11: 502.96 | G11: 0 | H11: Standard | I11: 2.67 | J11: 29.24 | K11: 495.01 | L11: =ROUND(K11*(I11/100)*(J11/100),4) -> 3.8646 | M11: 19 | N11: Guarantee | O11: AA | P11: No | Q11: 77.4 | R11: 05-Jun-2026 | S11: Real Estate | T11: Telangana | U11: Normal | V11: Green
A12: LN20009 | B12: Borrower_010 | C12: Corporate | D12: Auto Loan | E12: 2332.8 | F12: 864.16 | G12: 248 | H12: Doubtful-1 | I12: 43.46 | J12: 47.68 | K12: 881.26 | L12: =ROUND(K12*(I12/100)*(J12/100),4) -> 182.6123 | M12: 13.95 | N12: FD | O12: B | P12: Yes | Q12: 83 | R12: 25-Sep-2024 | S12: Real Estate | T12: Delhi | U12: High | V12: Red
A13: LN20010 | B13: Borrower_011 | C13: Agri | D13: MSME Loan | E13: 665.25 | F13: 610.4 | G13: 0 | H13: Standard | I13: 2.53 | J13: 21.1 | K13: 610.41 | L13: =ROUND(K13*(I13/100)*(J13/100),4) -> 3.2586 | M13: 12.68 | N13: Stocks | O13: AA+ | P13: No | Q13: 84.3 | R13: 16-Sep-2025 | S13: Shipping | T13: West Bengal | U13: Normal | V13: Green
A14: LN20011 | B14: Borrower_012 | C14: Corporate | D14: Working Capital | E14: 234.35 | F14: 211.04 | G14: 645 | H14: Doubtful-2 | I14: 60.9 | J14: 64.23 | K14: 215.2 | L14: =ROUND(K14*(I14/100)*(J14/100),4) -> 84.1778 | M14: 15.37 | N14: Immovable Property | O14: CCC | P14: Yes | Q14: 64.3 | R14: 25-May-2026 | S14: Coal | T14: Maharashtra | U14: High | V14: Red
... A202: LN20199 | B202: Borrower_200 | C202: Retail | D202: Home Loan | E202: 98.82 | F202: 61.77 | G202: 0 | H202: Standard | I202: 2.47 | J202: 28.52 | K202: 60.9 | L202: =ROUND(K202*(I202/100)*(J202/100),4) -> 0.429 | M202: 18.72 | N202: Clean | O202: AA | P202: No | Q202: 48.2 | R202: 30-Jul-2024 | S202: Retail | T202: MP | U202: Normal | V202: Green

Sheet P1_Market_Risk
A1: PILLAR 1 | Market Risk – Trading Book Positions | Bank Risk Management Dashboard
A2: Position_ID | B2: Trade_Date | C2: Desk | D2: Asset_Class | E2: Instrument | F2: Currency | G2: Face_Value_Cr | H2: MTM_Cr | I2: VaR_1D_Cr | J2: SVaR_Cr | K2: IRC_Cr | L2: ES_99_Cr | M2: Duration | N2: DV01_Lakhs | O2: Greeks_Delta | P2: Limit_Cr | Q2: Limit_Used_% | R2: Breach_Flag | S2: Rating | T2: Maturity_Date | U2: Status | V2: RAG
A3: POS00001 | B3: 24-Aug-2024 | C3: Commodity | D3: Corporate Bond | E3: Derivative | F3: JPY | G3: 606.65 | H3: 674.66 | I3: 21.0242 | J3: 57.4025 | K3: 15.0633 | L3: 26.9283 | M3: 4.74 | N3: 28.76 | O3: -0.727 | P3: 1383.91 | Q3: =ROUND(I3/P3*100,1) -> 1.5 | R3: No | S3: BBB | T3: 29-Mar-2036 | U3: Normal | V3: Green
A4: POS00002 | B4: 12-Aug-2025 | C4: Equity | D4: FX Forward | E4: Forward | F4: SGD | G4: 679.06 | H4: 718.93 | I4: 47.1535 | J4: 119.9769 | K4: 27.2825 | L4: 78.801 | M4: 2.88 | N4: 19.56 | O4: -0.386 | P4: 2810.83 | Q4: =ROUND(I4/P4*100,1) -> 1.7 | R4: No | S4: AA | T4: 31-Mar-2028 | U4: Normal | V4: Green
A5: POS00003 | B5: 02-Apr-2024 | C5: Equity | D5: Equity | E5: Derivative | F5: JPY | G5: 51.7 | H5: 53.79 | I5: 3.502 | J5: 9.6692 | K5: 2.0197 | L5: 5.7868 | M5: 14.07 | N5: 7.27 | O5: -0.719 | P5: 221.01 | Q5: =ROUND(I5/P5*100,1) -> 1.6 | R5: No | S5: A+ | T5: 31-Mar-2031 | U5: Normal | V5: Green
A6: POS00004 | B6: 22-Feb-2025 | C6: Corporate Bond | D6: Corporate Bond | E6: Derivative | F6: SGD | G6: 478.92 | H6: 510.46 | I6: 14.7097 | J6: 23.7367 | K6: 8.3514 | L6: 25.8088 | M6: 5.45 | N6: 26.1 | O6: 0.574 | P6: 2052.79 | Q6: =ROUND(I6/P6*100,1) -> 0.7 | R6: No | S6: AAA | T6: 30-Mar-2032 | U6: Normal | V6: Green
A7: POS00005 | B7: 23-Jun-2025 | C7: Equity | D7: Equity | E7: Forward | F7: GBP | G7: 360.36 | H7: 358.83 | I7: 15.0183 | J7: 25.8572 | K7: 11.7682 | L7: 28.4032 | M7: 9.87 | N7: 35.57 | O7: 0.374 | P7: 742.53 | Q7: =ROUND(I7/P7*100,1) -> 2 | R7: No | S7: AA+ | T7: 01-Apr-2026 | U7: Normal | V7: Green
A8: POS00006 | B8: 27-Jan-2025 | C8: G-Sec | D8: FX Forward | E8: Option | F8: INR | G8: 79.71 | H8: 76.05 | I8: 2.3787 | J8: 5.8953 | K8: 1.9925 | L8: 4.5635 | M8: 1.67 | N8: 1.33 | O8: 0.188 | P8: 277.41 | Q8: =ROUND(I8/P8*100,1) -> 0.9 | R8: No | S8: BB | T8: 29-Mar-2037 | U8: Normal | V8: Green
A9: POS00007 | B9: 02-May-2024 | C9: FX | D9: T-Bill | E9: Swap | F9: GBP | G9: 135.26 | H9: 127.18 | I9: 2.6382 | J9: 4.8226 | K9: 2.5268 | L9: 4.6897 | M9: 11.03 | N9: 14.92 | O9: -0.469 | P9: 316.08 | Q9: =ROUND(I9/P9*100,1) -> 0.8 | R9: No | S9: A+ | T9: 01-Apr-2027 | U9: Normal | V9: Green
A10: POS00008 | B10: 21-May-2024 | C10: FX | D10: Interest Rate Swap | E10: Derivative | F10: GBP | G10: 132.91 | H10: 131.87 | I10: 4.551 | J10: 8.8902 | K10: 4.2307 | L10: 7.6465 | M10: 3.24 | N10: 4.31 | O10: -0.949 | P10: 276.65 | Q10: =ROUND(I10/P10*100,1) -> 1.6 | R10: No | S10: A | T10: 01-Apr-2027 | U10: Normal | V10: Green
A11: POS00009 | B11: 29-Jul-2025 | C11: Commodity | D11: Corporate Bond | E11: Option | F11: GBP | G11: 345.53 | H11: 379.73 | I11: 9.2769 | J11: 21.9885 | K11: 6.5868 | L11: 13.8858 | M11: 5.91 | N11: 20.42 | O11: -0.627 | P11: 628.89 | Q11: =ROUND(I11/P11*100,1) -> 1.5 | R11: No | S11: BB | T11: 30-Mar-2033 | U11: Normal | V11: Green
A12: POS00010 | B12: 26-Dec-2024 | C12: Corporate Bond | D12: CD | E12: Swap | F12: INR | G12: 131.26 | H12: 139.04 | I12: 1.9459 | J12: 4.6736 | K12: 2.0365 | L12: 2.9795 | M12: 11.42 | N12: 14.99 | O12: -0.545 | P12: 238.24 | Q12: =ROUND(I12/P12*100,1) -> 0.8 | R12: No | S12: BBB | T12: 30-Mar-2034 | U12: Normal | V12: Green
A13: POS00011 | B13: 03-Jun-2025 | C13: Derivatives | D13: CDS | E13: Swap | F13: USD | G13: 349.1 | H13: 326.68 | I13: 20.8984 | J13: 51.3509 | K13: 16.7539 | L13: 40.1325 | M13: 12.07 | N13: 42.14 | O13: 0.355 | P13: 1199.23 | Q13: =ROUND(I13/P13*100,1) -> 1.7 | R13: No | S13: AA+ | T13: 30-Mar-2033 | U13: Normal | V13: Green
A14: POS00012 | B14: 25-Sep-2024 | C14: Corporate Bond | D14: CP | E14: Derivative | F14: USD | G14: 114.54 | H14: 115.08 | I14: 7.972 | J14: 16.9203 | K14: 9.549 | L14: 13.5666 | M14: 12.56 | N14: 14.39 | O14: -0.484 | P14: 539.47 | Q14: =ROUND(I14/P14*100,1) -> 1.5 | R14: No | S14: AA+ | T14: 01-Apr-2027 | U14: Normal | V14: Green
... A202: POS00200 | B202: 08-Jun-2024 | C202: Derivatives | D202: CP | E202: Forward | F202: EUR | G202: 189.88 | H202: 179 | I202: 6.7423 | J202: 18.3861 | K202: 5.826 | L202: 13.264 | M202: 3.38 | N202: 6.42 | O202: 0.49 | P202: 409.74 | Q202: =ROUND(I202/P202*100,1) -> 1.6 | R202: No | S202: A- | T202: 31-Mar-2030 | U202: Normal | V202: Green

Sheet P1_Operational_Risk
A1: PILLAR 1 | Operational Risk – Loss Event Register | Bank Risk Management Dashboard
A2: Incident_ID | B2: Date | C2: Business_Unit | D2: Risk_Category | E2: Event_Type | F2: Gross_Loss_Cr | G2: Net_Loss_Cr | H2: Recovery_Cr | I2: Frequency | J2: RCSA_Score | K2: KRI_Breach | L2: RCA_Done | M2: Control_Adequacy | N2: Residual_Risk | O2: BEL_Estimate_Cr | P2: Action_Owner | Q2: Target_Date | R2: Op_Capital_Cr | S2: Status | T2: RAG
A3: INC2024001 | B3: 30-May-2025 | C3: HR | D3: People Risk | E3: Fraud | F3: 0.427 | G3: =ROUND(F3-H3,2) -> 0.3 | H3: 0.1245 | I3: 16 | J3: 3 | K3: Yes | L3: No | M3: Weak | N3: Medium | O3: =ROUND(F3*I3*0.85,2) -> 5.81 | P3: Owner_40 | Q3: 07-Aug-2025 | R3: =ROUND(O3/100,2) -> 0.06 | S3: Open | T3: Amber
A4: INC2024002 | B4: 11-Jul-2024 | C4: Trade Finance | D4: Internal Fraud | E4: System Failure | F4: 2.3746 | G4: =ROUND(F4-H4,2) -> 1.96 | H4: 0.416 | I4: 3 | J4: 1.4 | K4: No | L4: Yes | M4: Adequate | N4: Medium | O4: =ROUND(F4*I4*0.85,2) -> 6.06 | P4: Owner_10 | Q4: 23-Apr-2026 | R4: =ROUND(O4/100,2) -> 0.06 | S4: Closed | T4: Amber
A5: INC2024003 | B5: 17-Jun-2025 | C5: Retail Banking | D5: People Risk | E5: Natural Disaster | F5: 5.819 | G5: =ROUND(F5-H5,2) -> 3.32 | H5: 2.4964 | I5: 5 | J5: 2.9 | K5: No | L5: No | M5: Strong | N5: Medium | O5: =ROUND(F5*I5*0.85,2) -> 24.73 | P5: Owner_13 | Q5: 04-Mar-2025 | R5: =ROUND(O5/100,2) -> 0.25 | S5: Open | T5: Amber
A6: INC2024004 | B6: 25-Aug-2024 | C6: Forex | D6: Technology Risk | E6: Natural Disaster | F6: 3.4933 | G6: =ROUND(F6-H6,2) -> 1.72 | H6: 1.7782 | I6: 11 | J6: 2.9 | K6: No | L6: No | M6: Weak | N6: High | O6: =ROUND(F6*I6*0.85,2) -> 32.66 | P6: Owner_9 | Q6: 05-May-2026 | R6: =ROUND(O6/100,2) -> 0.33 | S6: Overdue | T6: Amber
A7: INC2024005 | B7: 24-Jun-2024 | C7: Cards | D7: Process Risk | E7: Third Party Failure | F7: 2.2628 | G7: =ROUND(F7-H7,2) -> 1.69 | H7: 0.5696 | I7: 2 | J7: 1.6 | K7: No | L7: No | M7: Adequate | N7: High | O7: =ROUND(F7*I7*0.85,2) -> 3.85 | P7: Owner_11 | Q7: 30-Jan-2026 | R7: =ROUND(O7/100,2) -> 0.04 | S7: Overdue | T7: Amber
A8: INC2024006 | B8: 05-Jul-2024 | C8: ATM | D8: Cyber | E8: Process Error | F8: 1.4655 | G8: =ROUND(F8-H8,2) -> 1.35 | H8: 0.1155 | I8: 11 | J8: 3.3 | K8: No | L8: No | M8: Weak | N8: Low | O8: =ROUND(F8*I8*0.85,2) -> 13.7 | P8: Owner_14 | Q8: 14-Nov-2025 | R8: =ROUND(O8/100,2) -> 0.14 | S8: Open | T8: Amber
A9: INC2024007 | B9: 12-Nov-2025 | C9: IT | D9: Technology Risk | E9: Process Error | F9: 2.2688 | G9: =ROUND(F9-H9,2) -> 1.3 | H9: 0.9708 | I9: 6 | J9: 3.1 | K9: Yes | L9: Yes | M9: Inadequate | N9: Medium | O9: =ROUND(F9*I9*0.85,2) -> 11.57 | P9: Owner_50 | Q9: 15-Apr-2025 | R9: =ROUND(O9/100,2) -> 0.12 | S9: In Progress | T9: Amber
A10: INC2024008 | B10: 23-Nov-2024 | C10: ATM | D10: External Fraud | E10: Theft | F10: 5.8548 | G10: =ROUND(F10-H10,2) -> 4.2 | H10: 1.6504 | I10: 23 | J10: 2.2 | K10: No | L10: In Progress | M10: Adequate | N10: High | O10: =ROUND(F10*I10*0.85,2) -> 114.46 | P10: Owner_47 | Q10: 10-May-2026 | R10: =ROUND(O10/100,2) -> 1.14 | S10: In Progress | T10: Red
A11: INC2024009 | B11: 12-Dec-2024 | C11: Treasury | D11: Business Continuity | E11: Fraud | F11: 0.8796 | G11: =ROUND(F11-H11,2) -> 0.5 | H11: 0.3832 | I11: 10 | J11: 1.1 | K11: No | L11: No | M11: Weak | N11: Low | O11: =ROUND(F11*I11*0.85,2) -> 7.48 | P11: Owner_21 | Q11: 28-Feb-2025 | R11: =ROUND(O11/100,2) -> 0.07 | S11: Closed | T11: Green
A12: INC2024010 | B12: 20-Aug-2025 | C12: Forex | D12: Process Risk | E12: Regulatory Action | F12: 1.2145 | G12: =ROUND(F12-H12,2) -> 1.08 | H12: 0.1318 | I12: 15 | J12: 3.7 | K12: Yes | L12: In Progress | M12: Inadequate | N12: Low | O12: =ROUND(F12*I12*0.85,2) -> 15.48 | P12: Owner_32 | Q12: 12-Jul-2025 | R12: =ROUND(O12/100,2) -> 0.15 | S12: Open | T12: Red
A13: INC2024011 | B13: 13-Nov-2025 | C13: IT | D13: Legal/Compliance | E13: Process Error | F13: 4.31 | G13: =ROUND(F13-H13,2) -> 2.8 | H13: 1.5057 | I13: 13 | J13: 2.5 | K13: No | L13: No | M13: Weak | N13: Medium | O13: =ROUND(F13*I13*0.85,2) -> 47.63 | P13: Owner_29 | Q13: 23-Apr-2026 | R13: =ROUND(O13/100,2) -> 0.48 | S13: Open | T13: Amber
A14: INC2024012 | B14: 08-Aug-2024 | C14: Trade Finance | D14: Legal/Compliance | E14: Third Party Failure | F14: 1.7674 | G14: =ROUND(F14-H14,2) -> 0.68 | H14: 1.0851 | I14: 14 | J14: 3.9 | K14: No | L14: Yes | M14: Strong | N14: Low | O14: =ROUND(F14*I14*0.85,2) -> 21.03 | P14: Owner_14 | Q14: 05-Jul-2025 | R14: =ROUND(O14/100,2) -> 0.21 | S14: In Progress | T14: Red
... A202: INC2024200 | B202: 11-Jan-2025 | C202: Retail Banking | D202: Internal Fraud | E202: System Failure | F202: 0.5417 | G202: =ROUND(F202-H202,2) -> 0.33 | H202: 0.2126 | I202: 22 | J202: 4.6 | K202: No | L202: Yes | M202: Inadequate | N202: Medium | O202: =ROUND(F202*I202*0.85,2) -> 10.13 | P202: Owner_45 | Q202: 16-Feb-2026 | R202: =ROUND(O202/100,2) -> 0.1 | S202: Open | T202: Red

Sheet P1_Capital_Adequacy
A1: PILLAR 1 | Capital Adequacy – CRAR & RWA Trend | Bank Risk Management Dashboard
A2: Quarter | B2: CET1_Cr | C2: Tier1_Cr | D2: Tier2_Cr | E2: Total_Capital_Cr | F2: Credit_RWA_Cr | G2: Market_RWA_Cr | H2: Op_RWA_Cr | I2: Total_RWA_Cr | J2: CET1_% | K2: Tier1_% | L2: CRAR_% | M2: CCB_% | N2: D-SIB_Buffer_% | O2: Leverage_Ratio_% | P2: Capital_Buffer_Cr | Q2: ICAAP_Headroom_Cr | R2: RAG
A3: Q1-FY24 | B3: 321319 | C3: 338640 | D3: 59981 | E3: 398621 | F3: 1602419 | G3: 200602 | H3: 250179 | I3: 2053200 | J3: =ROUND(B3/I3*100,2) -> 15.65 | K3: =ROUND(C3/I3*100,2) -> 16.49 | L3: =ROUND(E3/I3*100,2) -> 19.41 | M3: 2.5 | N3: 0.6 | O3: =ROUND(C3/(I3*11)*100,2) -> 1.5 | P3: =ROUND(E3-I3*0.13,0) -> 131705 | Q3: =ROUND(E3-I3*0.15,0) -> 90641 | R3: Green
A4: Q2-FY24 | B4: 322979 | C4: 340199 | D4: 61217 | E4: 401416 | F4: 1628168 | G4: 202693 | H4: 253792 | I4: 2084653 | J4: =ROUND(B4/I4*100,2) -> 15.49 | K4: =ROUND(C4/I4*100,2) -> 16.32 | L4: =ROUND(E4/I4*100,2) -> 19.26 | M4: 2.5 | N4: 0.6 | O4: =ROUND(C4/(I4*11)*100,2) -> 1.48 | P4: =ROUND(E4-I4*0.13,0) -> 130411 | Q4: =ROUND(E4-I4*0.15,0) -> 88718 | R4: Green
A5: Q3-FY24 | B5: 327384 | C5: 345646 | D5: 61485 | E5: 407131 | F5: 1652425 | G5: 208165 | H5: 256048 | I5: 2116638 | J5: =ROUND(B5/I5*100,2) -> 15.47 | K5: =ROUND(C5/I5*100,2) -> 16.33 | L5: =ROUND(E5/I5*100,2) -> 19.23 | M5: 2.5 | N5: 0.6 | O5: =ROUND(C5/(I5*11)*100,2) -> 1.48 | P5: =ROUND(E5-I5*0.13,0) -> 131968 | Q5: =ROUND(E5-I5*0.15,0) -> 89635 | R5: Green
A6: Q4-FY24 | B6: 334797 | C6: 353736 | D6: 62521 | E6: 416257 | F6: 1668436 | G6: 213454 | H6: 260206 | I6: 2142096 | J6: =ROUND(B6/I6*100,2) -> 15.63 | K6: =ROUND(C6/I6*100,2) -> 16.51 | L6: =ROUND(E6/I6*100,2) -> 19.43 | M6: 2.5 | N6: 0.6 | O6: =ROUND(C6/(I6*11)*100,2) -> 1.5 | P6: =ROUND(E6-I6*0.13,0) -> 137785 | Q6: =ROUND(E6-I6*0.15,0) -> 94943 | R6: Green
A7: Q1-FY25 | B7: 341088 | C7: 359474 | D7: 63005 | E7: 422479 | F7: 1693048 | G7: 215824 | H7: 262787 | I7: 2171659 | J7: =ROUND(B7/I7*100,2) -> 15.71 | K7: =ROUND(C7/I7*100,2) -> 16.55 | L7: =ROUND(E7/I7*100,2) -> 19.45 | M7: 2.5 | N7: 0.6 | O7: =ROUND(C7/(I7*11)*100,2) -> 1.5 | P7: =ROUND(E7-I7*0.13,0) -> 140163 | Q7: =ROUND(E7-I7*0.15,0) -> 96730 | R7: Green
A8: Q2-FY25 | B8: 342185 | C8: 360541 | D8: 63226 | E8: 423767 | F8: 1716781 | G8: 219499 | H8: 265931 | I8: 2202211 | J8: =ROUND(B8/I8*100,2) -> 15.54 | K8: =ROUND(C8/I8*100,2) -> 16.37 | L8: =ROUND(E8/I8*100,2) -> 19.24 | M8: 2.5 | N8: 0.6 | O8: =ROUND(C8/(I8*11)*100,2) -> 1.49 | P8: =ROUND(E8-I8*0.13,0) -> 137480 | Q8: =ROUND(E8-I8*0.15,0) -> 93435 | R8: Green
A9: Q3-FY25 | B9: 346529 | C9: 366593 | D9: 64328 | E9: 430921 | F9: 1743206 | G9: 223003 | H9: 267794 | I9: 2234003 | J9: =ROUND(B9/I9*100,2) -> 15.51 | K9: =ROUND(C9/I9*100,2) -> 16.41 | L9: =ROUND(E9/I9*100,2) -> 19.29 | M9: 2.5 | N9: 0.6 | O9: =ROUND(C9/(I9*11)*100,2) -> 1.49 | P9: =ROUND(E9-I9*0.13,0) -> 140501 | Q9: =ROUND(E9-I9*0.15,0) -> 95821 | R9: Green
A10: Q4-FY25 | B10: 355804 | C10: 374662 | D10: 64781 | E10: 439443 | F10: 1774406 | G10: 226457 | H10: 271766 | I10: 2272629 | J10: =ROUND(B10/I10*100,2) -> 15.66 | K10: =ROUND(C10/I10*100,2) -> 16.49 | L10: =ROUND(E10/I10*100,2) -> 19.34 | M10: 2.5 | N10: 0.6 | O10: =ROUND(C10/(I10*11)*100,2) -> 1.5 | P10: =ROUND(E10-I10*0.13,0) -> 144001 | Q10: =ROUND(E10-I10*0.15,0) -> 98549 | R10: Green
A11: Q1-FY26 | B11: 359199 | C11: 379036 | D11: 65861 | E11: 444897 | F11: 1795343 | G11: 230100 | H11: 275332 | I11: 2300775 | J11: =ROUND(B11/I11*100,2) -> 15.61 | K11: =ROUND(C11/I11*100,2) -> 16.47 | L11: =ROUND(E11/I11*100,2) -> 19.34 | M11: 2.5 | N11: 0.6 | O11: =ROUND(C11/(I11*11)*100,2) -> 1.5 | P11: =ROUND(E11-I11*0.13,0) -> 145796 | Q11: =ROUND(E11-I11*0.15,0) -> 99781 | R11: Green
A12: Q2-FY26 | B12: 362448 | C12: 382633 | D12: 66094 | E12: 448727 | F12: 1811811 | G12: 235791 | H12: 276272 | I12: 2323874 | J12: =ROUND(B12/I12*100,2) -> 15.6 | K12: =ROUND(C12/I12*100,2) -> 16.47 | L12: =ROUND(E12/I12*100,2) -> 19.31 | M12: 2.5 | N12: 0.6 | O12: =ROUND(C12/(I12*11)*100,2) -> 1.5 | P12: =ROUND(E12-I12*0.13,0) -> 146623 | Q12: =ROUND(E12-I12*0.15,0) -> 100146 | R12: Green
A13: Q3-FY26 | B13: 366393 | C13: 386361 | D13: 67647 | E13: 454008 | F13: 1846812 | G13: 237903 | H13: 279205 | I13: 2363920 | J13: =ROUND(B13/I13*100,2) -> 15.5 | K13: =ROUND(C13/I13*100,2) -> 16.34 | L13: =ROUND(E13/I13*100,2) -> 19.21 | M13: 2.5 | N13: 0.6 | O13: =ROUND(C13/(I13*11)*100,2) -> 1.49 | P13: =ROUND(E13-I13*0.13,0) -> 146698 | Q13: =ROUND(E13-I13*0.15,0) -> 99420 | R13: Green
A14: Q4-FY26 | B14: 372064 | C14: 392022 | D14: 68086 | E14: 460108 | F14: 1859378 | G14: 239037 | H14: 282665 | I14: 2381080 | J14: =ROUND(B14/I14*100,2) -> 15.63 | K14: =ROUND(C14/I14*100,2) -> 16.46 | L14: =ROUND(E14/I14*100,2) -> 19.32 | M14: 2.5 | N14: 0.6 | O14: =ROUND(C14/(I14*11)*100,2) -> 1.5 | P14: =ROUND(E14-I14*0.13,0) -> 150568 | Q14: =ROUND(E14-I14*0.15,0) -> 102946 | R14: Green

Sheet P2_Liquidity_Risk
A1: PILLAR 2 | Liquidity Risk – LCR/NSFR/Gap Analysis | Bank Risk Management Dashboard
A2: Record_ID | B2: Date | C2: Time_Bucket | D2: Inflow_Cr | E2: Outflow_Cr | F2: Net_Gap_Cr | G2: Cumul_Gap_Cr | H2: LCR_% | I2: NSFR_% | J2: SLR_% | K2: CRR_% | L2: HQLA_Cr | M2: HQLA_L1_Cr | N2: HQLA_L2_Cr | O2: Net_Cash_Outflow_30D_Cr | P2: Stress_Scenario | Q2: NSFR_RSF_Cr | R2: NSFR_ASF_Cr | S2: Status | T2: RAG
A3: LIQ00001 | B3: 07-Jul-2025 | C3: 8-14 Days | D3: 2460.35 | E3: 591.2 | F3: =ROUND(D3-E3,2) -> 1869.15 | G3: =ROUND(F3,2) -> 1869.15 | H3: =ROUND(L3/O3*100,2) -> 141.67 | I3: =ROUND(R3/Q3*100,2) -> 122.87 | J3: 23.06 | K3: 3.64 | L3: 3616.8 | M3: 2928.42 | N3: 688.38 | O3: 2552.96 | P3: Moderate Stress | Q3: 17944.31 | R3: 22048.55 | S3: Normal | T3: Green
A4: LIQ00002 | B4: 08-Jul-2024 | C4: 2-3 Months | D4: 3425.49 | E4: 3921.85 | F4: =ROUND(D4-E4,2) -> -496.36 | G4: =ROUND(G3+F4,2) -> 1372.79 | H4: =ROUND(L4/O4*100,2) -> 149.29 | I4: =ROUND(R4/Q4*100,2) -> 119.14 | J4: 21.19 | K4: 5.08 | L4: 5532.84 | M4: 4677.71 | N4: 855.13 | O4: 3706 | P4: Severe Stress | Q4: 6310.92 | R4: 7519.1 | S4: Normal | T4: Green
A5: LIQ00003 | B5: 10-May-2024 | C5: 1-2 Months | D5: 835.27 | E5: 748.94 | F5: =ROUND(D5-E5,2) -> 86.33 | G5: =ROUND(G4+F5,2) -> 1459.12 | H5: =ROUND(L5/O5*100,2) -> 138.41 | I5: =ROUND(R5/Q5*100,2) -> 126.92 | J5: 21.58 | K5: 4.17 | L5: 5733.27 | M5: 4928.91 | N5: 804.36 | O5: 4142.22 | P5: Moderate Stress | Q5: 7755.96 | R5: 9844.17 | S5: Normal | T5: Green
A6: LIQ00004 | B6: 19-Aug-2024 | C6: Overnight | D6: 677.89 | E6: 5878.96 | F6: =ROUND(D6-E6,2) -> -5201.07 | G6: =ROUND(G5+F6,2) -> -3741.95 | H6: =ROUND(L6/O6*100,2) -> 146.96 | I6: =ROUND(R6/Q6*100,2) -> 127.27 | J6: 19.55 | K6: 4.55 | L6: 3633.88 | M6: 2711.13 | N6: 922.75 | O6: 2472.63 | P6: Moderate Stress | Q6: 13065.92 | R6: 16629.25 | S6: Normal | T6: Green
A7: LIQ00005 | B7: 19-May-2024 | C7: 1-3Y | D7: 2158.51 | E7: 3475.73 | F7: =ROUND(D7-E7,2) -> -1317.22 | G7: =ROUND(G6+F7,2) -> -5059.17 | H7: =ROUND(L7/O7*100,2) -> 105.94 | I7: =ROUND(R7/Q7*100,2) -> 127.24 | J7: 18.91 | K7: 4.14 | L7: 3754.22 | M7: 3117.58 | N7: 636.64 | O7: 3543.59 | P7: Severe Stress | Q7: 8168.07 | R7: 10393.33 | S7: Watch | T7: Amber
A8: LIQ00006 | B8: 14-Mar-2025 | C8: 1-3Y | D8: 3354.86 | E8: 5303.92 | F8: =ROUND(D8-E8,2) -> -1949.06 | G8: =ROUND(G7+F8,2) -> -7008.23 | H8: =ROUND(L8/O8*100,2) -> 115.54 | I8: =ROUND(R8/Q8*100,2) -> 117.7 | J8: 24.34 | K8: 4.93 | L8: 4995.24 | M8: 3938.03 | N8: 1057.21 | O8: 4323.25 | P8: Mild Stress | Q8: 7712.04 | R8: 9077.26 | S8: Watch | T8: Amber
A9: LIQ00007 | B9: 15-Aug-2024 | C9: Overnight | D9: 5518.81 | E9: 3871.24 | F9: =ROUND(D9-E9,2) -> 1647.57 | G9: =ROUND(G8+F9,2) -> -5360.66 | H9: =ROUND(L9/O9*100,2) -> 140.69 | I9: =ROUND(R9/Q9*100,2) -> 126.94 | J9: 22.06 | K9: 4.42 | L9: 4852.59 | M9: 3717.02 | N9: 1135.57 | O9: 3449.06 | P9: Severe Stress | Q9: 17834.96 | R9: 22639.48 | S9: Normal | T9: Green
A10: LIQ00008 | B10: 14-Dec-2024 | C10: 1-2 Months | D10: 1727.36 | E10: 2623.81 | F10: =ROUND(D10-E10,2) -> -896.45 | G10: =ROUND(G9+F10,2) -> -6257.11 | H10: =ROUND(L10/O10*100,2) -> 148.84 | I10: =ROUND(R10/Q10*100,2) -> 107.51 | J10: 21.09 | K10: 5.22 | L10: 10084.22 | M10: 7603.4 | N10: 2480.82 | O10: 6775.14 | P10: Moderate Stress | Q10: 10878.18 | R10: 11695.07 | S10: Watch | T10: Amber
A11: LIQ00009 | B11: 17-May-2024 | C11: 5+ Years | D11: 568.9 | E11: 4406.72 | F11: =ROUND(D11-E11,2) -> -3837.82 | G11: =ROUND(G10+F11,2) -> -10094.93 | H11: =ROUND(L11/O11*100,2) -> 103.44 | I11: =ROUND(R11/Q11*100,2) -> 95.43 | J11: 24.82 | K11: 4.61 | L11: 9020.67 | M11: 7625.1 | N11: 1395.57 | O11: 8720.28 | P11: Severe Stress | Q11: 15700.16 | R11: 14982.32 | S11: High | T11: Red
A12: LIQ00010 | B12: 30-Jul-2025 | C12: 3-6 Months | D12: 4094.5 | E12: 5601.4 | F12: =ROUND(D12-E12,2) -> -1506.9 | G12: =ROUND(G11+F12,2) -> -11601.83 | H12: =ROUND(L12/O12*100,2) -> 141.11 | I12: =ROUND(R12/Q12*100,2) -> 119.65 | J12: 24.25 | K12: 4.56 | L12: 2658.7 | M12: 2127.71 | N12: 530.99 | O12: 1884.17 | P12: Base | Q12: 10865.66 | R12: 13000.92 | S12: Normal | T12: Green
A13: LIQ00011 | B13: 11-Jul-2025 | C13: Overnight | D13: 4313.54 | E13: 4245.29 | F13: =ROUND(D13-E13,2) -> 68.25 | G13: =ROUND(G12+F13,2) -> -11533.58 | H13: =ROUND(L13/O13*100,2) -> 144.34 | I13: =ROUND(R13/Q13*100,2) -> 133.59 | J13: 26.58 | K13: 5.15 | L13: 7550.02 | M13: 6297.74 | N13: 1252.28 | O13: 5230.76 | P13: Base | Q13: 13288.48 | R13: 17751.53 | S13: Normal | T13: Green
A14: LIQ00012 | B14: 12-Mar-2025 | C14: 1-3Y | D14: 5432.41 | E14: 1131.4 | F14: =ROUND(D14-E14,2) -> 4301.01 | G14: =ROUND(G13+F14,2) -> -7232.57 | H14: =ROUND(L14/O14*100,2) -> 121.2 | I14: =ROUND(R14/Q14*100,2) -> 99.53 | J14: 18.93 | K14: 4.49 | L14: 4348.89 | M14: 3695.95 | N14: 652.94 | O14: 3588.27 | P14: Mild Stress | Q14: 10479.4 | R14: 10430.08 | S14: High | T14: Red
A15: LIQ00013 | B15: 12-Jul-2025 | C15: 5+ Years | D15: 1573.61 | E15: 3280.81 | F15: =ROUND(D15-E15,2) -> -1707.2 | G15: =ROUND(G14+F15,2) -> -8939.77 | H15: =ROUND(L15/O15*100,2) -> 117.95 | I15: =ROUND(R15/Q15*100,2) -> 107.19 | J15: 21 | K15: 3.93 | L15: 7524.49 | M15: 6411.61 | N15: 1112.88 | O15: 6379.35 | P15: Severe Stress | Q15: 8609.56 | R15: 9228.83 | S15: Watch | T15: Amber
... A202: LIQ00200 | B202: 17-Aug-2024 | C202: 2-7 Days | D202: 551.51 | E202: 3076.61 | F202: =ROUND(D202-E202,2) -> -2525.1 | G202: =ROUND(G201+F202,2) -> -22226.3 | H202: =ROUND(L202/O202*100,2) -> 101.21 | I202: =ROUND(R202/Q202*100,2) -> 118.53 | J202: 24.81 | K202: 4.58 | L202: 7758.07 | M202: 5983.73 | N202: 1774.34 | O202: 7665.38 | P202: Mild Stress | Q202: 7146.68 | R202: 8470.8 | S202: Watch | T202: Amber

Sheet P2_IRRBB
A1: PILLAR 2 | IRRBB – Interest Rate Risk in Banking Book | Bank Risk Management Dashboard
A2: Record_ID | B2: Date | C2: Rate_Shock_bps | D2: Asset_Repricing_Cr | E2: Liability_Repricing_Cr | F2: Repricing_Gap_Cr | G2: NII_Impact_Cr | H2: NII_Impact_% | I2: EVE_Impact_Cr | J2: EVE_Impact_Pct_Tier1 | K2: Duration_Assets_Yrs | L2: Duration_Liab_Yrs | M2: Duration_Gap_Yrs | N2: MCLR_1Y_% | O2: Base_Rate_% | P2: Deposit_Rate_% | Q2: Yield_Portfolio_% | R2: Delta_NII_Parallel_Up | S2: Delta_NII_Parallel_Down | T2: Delta_NII_Steepener | U2: Scenario | V2: Status | W2: RAG
A3: IRR0001 | B3: 04-Feb-2025 | C3: 100 | D3: 179776.61 | E3: 164523.34 | F3: =ROUND(D3-E3,2) -> 15253.27 | G3: =ROUND(F3*C3/10000,2) -> 152.53 | H3: =ROUND(G3/320000*100,2) -> 0.05 | I3: =ROUND(F3*M3*C3/10000,2) -> 655.89 | J3: =ROUND(I3/380000*100,2) -> 0.17 | K3: 7.21 | L3: 2.91 | M3: =ROUND(K3-L3,2) -> 4.3 | N3: 9.76 | O3: 9.26 | P3: 5.91 | Q3: 9.07 | R3: 290.68 | S3: -314.59 | T3: 89.77 | U3: +200bps | V3: Normal | W3: Green
A4: IRR0002 | B4: 15-Mar-2025 | C4: -100 | D4: 106670.35 | E4: 114696.38 | F4: =ROUND(D4-E4,2) -> -8026.03 | G4: =ROUND(F4*C4/10000,2) -> 80.26 | H4: =ROUND(G4/320000*100,2) -> 0.03 | I4: =ROUND(F4*M4*C4/10000,2) -> 151.69 | J4: =ROUND(I4/380000*100,2) -> 0.04 | K4: 4.17 | L4: 2.28 | M4: =ROUND(K4-L4,2) -> 1.89 | N4: 9.69 | O4: 9.19 | P4: 6.52 | Q4: 8.72 | R4: -167.83 | S4: 175.01 | T4: 56.59 | U4: Bull Flat | V4: Normal | W4: Green
A5: IRR0003 | B5: 08-Apr-2025 | C5: 100 | D5: 149345.54 | E5: 72738.11 | F5: =ROUND(D5-E5,2) -> 76607.43 | G5: =ROUND(F5*C5/10000,2) -> 766.07 | H5: =ROUND(G5/320000*100,2) -> 0.24 | I5: =ROUND(F5*M5*C5/10000,2) -> 3156.23 | J5: =ROUND(I5/380000*100,2) -> 0.83 | K5: 7.13 | L5: 3.01 | M5: =ROUND(K5-L5,2) -> 4.12 | N5: 9.31 | O5: 8.81 | P5: 5.33 | Q5: 8.4 | R5: 1627.04 | S5: -1677.95 | T5: -335.66 | U5: +300bps | V5: Normal | W5: Green
A6: IRR0004 | B6: 31-Jul-2024 | C6: 300 | D6: 151209.14 | E6: 79227.77 | F6: =ROUND(D6-E6,2) -> 71981.37 | G6: =ROUND(F6*C6/10000,2) -> 2159.44 | H6: =ROUND(G6/320000*100,2) -> 0.67 | I6: =ROUND(F6*M6*C6/10000,2) -> 323.92 | J6: =ROUND(I6/380000*100,2) -> 0.09 | K6: 4.92 | L6: 4.77 | M6: =ROUND(K6-L6,2) -> 0.15 | N6: 9.39 | O6: 8.89 | P6: 7.52 | Q6: 10.42 | R6: 1516.62 | S6: -1368.23 | T6: 377.6 | U6: +100bps | V6: Normal | W6: Green
